Workbook

Sheet Parametres
A1: Sampling parameters (Krejcie & Morgan / Cochran + Kish design effect)
A3: Niveau de confiance | B3: 0.9
A4: Marge d'erreur | B4: 0.1
A5: Proportion attendue (p) | B5: 0.5 | C5: Ne jamais touché ici sans demander l'avis de Yams Bindje ou HQ
A6: Coefficient intra-grappe (ICC) | B6: 0.06
A7: Taille moyenne de grappe (M) | B7: 6
A8: Tampon / buffer (non-réponse) | B8: 0.1
A11: Total sampling Host | B11: Total sampling PDI | C11: Total sampling Retournée | D11: Total sampling Réfugié | F11: PCODE | G11: Admin1 | H11: PCODE | I11: Admin2 | J11: Organisation | K11: PND | L11: PDI | M11: Réfugiés | N11: Rétournees | O11: Total | S11: PCODE | T11: Admin1 | U11: PCODE | V11: Admin2 | W11: PCODE | X11: Admin3 | Y11: Organisation | Z11: Representativity | AA11: PND | AB11: PDI | AC11: Réfugiés | AD11: Rétournees | AE11: Total
A12: 4854 | B12: 2106 | C12: 1746 | D12: 600 | F12: CM004 | G12: Extrême-Nord | H12: CM004001 | I12: Diamaré | J12: IOM | K12: 918 | L12: 312 | M12: 0 | N12: 0 | O12: 1230 | S12: CM004 | T12: Extrême-Nord | U12: CM004001 | V12: Diamaré | W12: CM004001001 | X12: Bogo | Y12: IOM | Z12: Admin3 | AA12: 102 | AB12: 66 | AC12: 0 | AD12: 0 | AE12: 168
F13: CM004 | G13: Extrême-Nord | H13: CM004002 | I13: Logone-et-Chari | J13: IOM | K13: 984 | L13: 666 | M13: 342 | N13: 480 | O13: 2472 | S13: CM004 | T13: Extrême-Nord | U13: CM004001 | V13: Diamaré | W13: CM004001002 | X13: Dargala | Y13: IOM | Z13: Admin3 | AA13: 102 | AB13: 0 | AC13: 0 | AD13: 0 | AE13: 102
F14: CM004 | G14: Extrême-Nord | H14: CM004003 | I14: Mayo-Danay | J14: IOM | K14: 1116 | L14: 342 | M14: 0 | N14: 756 | O14: 2214 | S14: CM004 | T14: Extrême-Nord | U14: CM004001 | V14: Diamaré | W14: CM004001003 | X14: Gazawa | Y14: IOM | Z14: Admin3 | AA14: 102 | AB14: 0 | AC14: 0 | AD14: 0 | AE14: 102
B15: TOTAL | F15: CM004 | G15: Extrême-Nord | H15: CM004004 | I15: Mayo-Kani | J15: IOM | K15: 714 | L15: 132 | M15: 0 | N15: 0 | O15: 846 | S15: CM004 | T15: Extrême-Nord | U15: CM004001 | V15: Diamaré | W15: CM004001004 | X15: Maroua 1er | Y15: IOM | Z15: Admin3 | AA15: 102 | AB15: 48 | AC15: 0 | AD15: 0 | AE15: 150
B16: 9306 | F16: CM004 | G16: Extrême-Nord | H16: CM004005 | I16: Mayo-Sava | J16: IOM | K16: 306 | L16: 228 | M16: 72 | N16: 156 | O16: 762 | S16: CM004 | T16: Extrême-Nord | U16: CM004001 | V16: Diamaré | W16: CM004001005 | X16: Maroua 2e | Y16: IOM | Z16: Admin3 | AA16: 102 | AB16: 66 | AC16: 0 | AD16: 0 | AE16: 168
F17: CM004 | G17: Extrême-Nord | H17: CM004006 | I17: Mayo-Tsanaga | J17: IOM | K17: 714 | L17: 354 | M17: 186 | N17: 276 | O17: 1530 | S17: CM004 | T17: Extrême-Nord | U17: CM004001 | V17: Diamaré | W17: CM004001006 | X17: Maroua 3e | Y17: IOM | Z17: Admin3 | AA17: 102 | AB17: 66 | AC17: 0 | AD17: 0 | AE17: 168
F18: CM010 | G18: Sud-Ouest | H18: CM010006 | I18: Ndian | J18: IOM | K18: 102 | L18: 72 | M18: 0 | N18: 78 | O18: 252 | S18: CM004 | T18: Extrême-Nord | U18: CM004001 | V18: Diamaré | W18: CM004001007 | X18: Meri | Y18: IOM | Z18: Admin3 | AA18: 102 | AB18: 0 | AC18: 0 | AD18: 0 | AE18: 102
S19: CM004 | T19: Extrême-Nord | U19: CM004001 | V19: Diamaré | W19: CM004001008 | X19: Ndoukoula | Y19: IOM | Z19: Admin3 | AA19: 102 | AB19: 0 | AC19: 0 | AD19: 0 | AE19: 102
S20: CM004 | T20: Extrême-Nord | U20: CM004001 | V20: Diamaré | W20: CM004001009 | X20: Pette | Y20: IOM | Z20: Admin3 | AA20: 102 | AB20: 66 | AC20: 0 | AD20: 0 | AE20: 168
S21: CM004 | T21: Extrême-Nord | U21: CM004002 | V21: Logone-et-Chari | W21: CM004002001 | X21: Blangoua | Y21: IOM | Z21: Admin3 | AA21: 78 | AB21: 78 | AC21: 0 | AD21: 66 | AE21: 222
S22: CM004 | T22: Extrême-Nord | U22: CM004002 | V22: Logone-et-Chari | W22: CM004002002 | X22: Darak | Y22: IOM | Z22: Admin3 | AA22: 102 | AB22: 66 | AC22: 0 | AD22: 0 | AE22: 168
S23: CM004 | T23: Extrême-Nord | U23: CM004002 | V23: Logone-et-Chari | W23: CM004002003 | X23: Fotokol | Y23: IOM | Z23: Admin3 | AA23: 96 | AB23: 78 | AC23: 72 | AD23: 78 | AE23: 324
S24: CM004 | T24: Extrême-Nord | U24: CM004002 | V24: Logone-et-Chari | W24: CM004002004 | X24: Goulfey | Y24: IOM | Z24: Admin3 | AA24: 102 | AB24: 72 | AC24: 0 | AD24: 48 | AE24: 222
S25: CM004 | T25: Extrême-Nord | U25: CM004002 | V25: Logone-et-Chari | W25: CM004002005 | X25: Hile-Alifa | Y25: IOM | Z25: Admin3 | AA25: 102 | AB25: 78 | AC25: 0 | AD25: 0 | AE25: 180
S26: CM004 | T26: Extrême-Nord | U26: CM004002 | V26: Logone-et-Chari | W26: CM004002006 | X26: Kousseri | Y26: IOM | Z26: Admin3 | AA26: 102 | AB26: 72 | AC26: 72 | AD26: 78 | AE26: 324
S27: CM004 | T27: Extrême-Nord | U27: CM004002 | V27: Logone-et-Chari | W27: CM004002007 | X27: Logone-Birni | Y27: IOM | Z27: Admin3 | AA27: 102 | AB27: 72 | AC27: 48 | AD27: 78 | AE27: 300
S28: CM004 | T28: Extrême-Nord | U28: CM004002 | V28: Logone-et-Chari | W28: CM004002008 | X28: Makary | Y28: IOM | Z28: Admin3 | AA28: 102 | AB28: 78 | AC28: 78 | AD28: 66 | AE28: 324
S29: CM004 | T29: Extrême-Nord | U29: CM004002 | V29: Logone-et-Chari | W29: CM004002009 | X29: Waza | Y29: IOM | Z29: Admin3 | AA29: 96 | AB29: 72 | AC29: 72 | AD29: 66 | AE29: 306
S30: CM004 | T30: Extrême-Nord | U30: CM004002 | V30: Logone-et-Chari | W30: CM004002010 | X30: Zina | Y30: IOM | Z30: Admin3 | AA30: 102 | AB30: 0 | AC30: 0 | AD30: 0 | AE30: 102
... S58: CM004 | T58: Extrême-Nord | U58: CM004006 | V58: Mayo-Tsanaga | W58: CM004006007 | X58: Soulede-Roua | Y58: IOM | Z58: Admin3 | AA58: 102 | AB58: 54 | AC58: 78 | AD58: 0 | AE58: 234
S59: CM010 | T59: Sud-Ouest | U59: CM010006 | V59: Ndian | W59: CM010006 | Y59: IOM | Z59: Admin2 | AA59: 102 | AB59: 72 | AC59: 0 | AD59: 78 | AE59: 252

Sheet host
A1: PCODE | B1: Admin1 | C1: PCODE | D1: Admin2 | E1: PCODE | F1: Admin3 | G1: Pop admin3 | H1: p | I1: buffer | J1: ci (AE8) | K1: marge d'erreur | M1: sample | N1: final adjusted | O1: final adjusted up to multiple of 6 | P1: enquete a faire sans buffer | Q1: enquetes de buffer | R1: nombre de clusters à tirer | S1: weights adjusted
A2: CM004 | B2: Extrême-Nord | C2: CM004001 | D2: Diamaré | E2: CM004001001 | F2: Bogo | G2: 131053.75 | H2: 0.5 | I2: 0.1 | J2: 0.9 | K2: 0.1 | M2: 75 | N2: 98 | O2: 102 | P2: 89 | Q2: 13 | R2: 17 | S2: 2.1729737
A3: CM004 | B3: Extrême-Nord | C3: CM004001 | D3: Diamaré | E3: CM004001002 | F3: Dargala | G3: 76741.11 | H3: 0.5 | I3: 0.1 | J3: 0.9 | K3: 0.1 | M3: 75 | N3: 98 | O3: 102 | P3: 89 | Q3: 13 | R3: 17 | S3: 1.2724277
A4: CM004 | B4: Extrême-Nord | C4: CM004001 | D4: Diamaré | E4: CM004001003 | F4: Gazawa | G4: 31985.865 | H4: 0.5 | I4: 0.1 | J4: 0.9 | K4: 0.1 | M4: 74 | N4: 97 | O4: 102 | P4: 88 | Q4: 14 | R4: 17 | S4: 0.53035069
A5: CM004 | B5: Extrême-Nord | C5: CM004001 | D5: Diamaré | E5: CM004001004 | F5: Maroua 1er | G5: 158216.47 | H5: 0.5 | I5: 0.1 | J5: 0.9 | K5: 0.1 | M5: 75 | N5: 98 | O5: 102 | P5: 89 | Q5: 13 | R5: 17 | S5: 2.6233531 | V5: sample size per cluster | W5: ICC | X5: Marge d'erreur
A6: CM004 | B6: Extrême-Nord | C6: CM004001 | D6: Diamaré | E6: CM004001005 | F6: Maroua 2e | G6: 42673.511 | H6: 0.5 | I6: 0.1 | J6: 0.9 | K6: 0.1 | M6: 75 | N6: 98 | O6: 102 | P6: 89 | Q6: 13 | R6: 17 | S6: 0.70756024 | V6: 6 | W6: 0.06 | X6: 0.1
A7: CM004 | B7: Extrême-Nord | C7: CM004001 | D7: Diamaré | E7: CM004001006 | F7: Maroua 3e | G7: 131620.14 | H7: 0.5 | I7: 0.1 | J7: 0.9 | K7: 0.1 | M7: 75 | N7: 98 | O7: 102 | P7: 89 | Q7: 13 | R7: 17 | S7: 2.182365
A8: CM004 | B8: Extrême-Nord | C8: CM004001 | D8: Diamaré | E8: CM004001007 | F8: Meri | G8: 100035.55 | H8: 0.5 | I8: 0.1 | J8: 0.9 | K8: 0.1 | M8: 75 | N8: 98 | O8: 102 | P8: 89 | Q8: 13 | R8: 17 | S8: 1.6586678
A9: CM004 | B9: Extrême-Nord | C9: CM004001 | D9: Diamaré | E9: CM004001008 | F9: Ndoukoula | G9: 57705.339 | H9: 0.5 | I9: 0.1 | J9: 0.9 | K9: 0.1 | M9: 75 | N9: 98 | O9: 102 | P9: 89 | Q9: 13 | R9: 17 | S9: 0.95679972
A10: CM004 | B10: Extrême-Nord | C10: CM004001 | D10: Diamaré | E10: CM004001009 | F10: Pette | G10: 27111.333 | H10: 0.5 | I10: 0.1 | J10: 0.9 | K10: 0.1 | M10: 74 | N10: 97 | O10: 102 | P10: 88 | Q10: 14 | R10: 17 | S10: 0.44952714
A11: CM004 | B11: Extrême-Nord | C11: CM004002 | D11: Logone-et-Chari | E11: CM004002001 | F11: Blangoua | G11: 272.11134 | H11: 0.5 | I11: 0.1 | J11: 0.9 | K11: 0.1 | M11: 60 | N11: 78 | O11: 78 | P11: 71 | Q11: 7 | R11: 13 | S11: 0.0059000712
A12: CM004 | B12: Extrême-Nord | C12: CM004002 | D12: Logone-et-Chari | E12: CM004002002 | F12: Darak | G12: 4612.1818 | H12: 0.5 | I12: 0.1 | J12: 0.9 | K12: 0.1 | M12: 74 | N12: 97 | O12: 102 | P12: 88 | Q12: 14 | R12: 17 | S12: 0.076473587
A13: CM004 | B13: Extrême-Nord | C13: CM004002 | D13: Logone-et-Chari | E13: CM004002003 | F13: Fotokol | G13: 3029.0201 | H13: 0.5 | I13: 0.1 | J13: 0.9 | K13: 0.1 | M13: 73 | N13: 95 | O13: 96 | P13: 86 | Q13: 10 | R13: 16 | S13: 0.053362497
A14: CM004 | B14: Extrême-Nord | C14: CM004002 | D14: Logone-et-Chari | E14: CM004002004 | F14: Goulfey | G14: 57598.573 | H14: 0.5 | I14: 0.1 | J14: 0.9 | K14: 0.1 | M14: 75 | N14: 98 | O14: 102 | P14: 89 | Q14: 13 | R14: 17 | S14: 0.95502945
A15: CM004 | B15: Extrême-Nord | C15: CM004002 | D15: Logone-et-Chari | E15: CM004002005 | F15: Hile-Alifa | G15: 12032.082 | H15: 0.5 | I15: 0.1 | J15: 0.9 | K15: 0.1 | M15: 74 | N15: 97 | O15: 102 | P15: 88 | Q15: 14 | R15: 17 | S15: 0.19950134
A16: CM004 | B16: Extrême-Nord | C16: CM004002 | D16: Logone-et-Chari | E16: CM004002006 | F16: Kousseri | G16: 47704.645 | H16: 0.5 | I16: 0.1 | J16: 0.9 | K16: 0.1 | M16: 75 | N16: 98 | O16: 102 | P16: 89 | Q16: 13 | R16: 17 | S16: 0.79098037
A17: CM004 | B17: Extrême-Nord | C17: CM004002 | D17: Logone-et-Chari | E17: CM004002007 | F17: Logone-Birni | G17: 31588.298 | H17: 0.5 | I17: 0.1 | J17: 0.9 | K17: 0.1 | M17: 74 | N17: 97 | O17: 102 | P17: 88 | Q17: 14 | R17: 17 | S17: 0.52375872
A18: CM004 | B18: Extrême-Nord | C18: CM004002 | D18: Logone-et-Chari | E18: CM004002008 | F18: Makary | G18: 45069.508 | H18: 0.5 | I18: 0.1 | J18: 0.9 | K18: 0.1 | M18: 75 | N18: 98 | O18: 102 | P18: 89 | Q18: 13 | R18: 17 | S18: 0.74728774
... A48: CM004 | B48: Extrême-Nord | C48: CM004006 | D48: Mayo-Tsanaga | E48: CM004006007 | F48: Soulede-Roua | G48: 24598.323 | H48: 0.5 | I48: 0.1 | J48: 0.9 | K48: 0.1 | M48: 74 | N48: 97 | O48: 102 | P48: 88 | Q48: 14 | R48: 17 | S48: 0.40785946
A49: CM010 | B49: Sud-Ouest | C49: CM010006 | D49: Ndian | E49: CM010006 | G49: 56181.13 | M49: 75 | N49: 98 | O49: 102 | P49: 98 | Q49: 4 | R49: 17 | S49: 0.93152715

Sheet IDP
A1: PCODE | B1: Admin1 | C1: PCODE | D1: Admin2 | E1: PCODE | F1: Admin3 | G1: Pop admin3 | H1: p | I1: buffer | J1: ci (AE8) | K1: marge d'erreur | M1: sample admin2 | N1: final adjusted up to multiple of 6 | O1: enquete a faire sans buffer | P1: enquetes de buffer | Q1: nombre de clusters à tirer | R1: weights adjusted
A2: CM004 | B2: Extrême-Nord | C2: CM004001 | D2: Diamaré | E2: CM004001001 | F2: Bogo | G2: 439.83333 | H2: 0.5 | I2: 0.1 | J2: 0.9 | K2: 0.1 | M2: 65 | N2: 66 | O2: 59 | P2: 7 | Q2: 11 | R2: 0.16192338
A3: CM004 | B3: Extrême-Nord | C3: CM004001 | D3: Diamaré | E3: CM004001002 | F3: Dargala | G3: 0 | H3: 0.5 | I3: 0.1 | J3: 0.9 | K3: 0.1 | M3: 0 | N3: 0 | O3: 0 | P3: 0 | Q3: 0 | R3: #DIV/0!
A4: CM004 | B4: Extrême-Nord | C4: CM004001 | D4: Diamaré | E4: CM004001003 | F4: Gazawa | G4: 0 | H4: 0.5 | I4: 0.1 | J4: 0.9 | K4: 0.1 | M4: 0 | N4: 0 | O4: 0 | P4: 0 | Q4: 0 | R4: #DIV/0!
A5: CM004 | B5: Extrême-Nord | C5: CM004001 | D5: Diamaré | E5: CM004001004 | F5: Maroua 1er | G5: 109 | H5: 0.5 | I5: 0.1 | J5: 0.9 | K5: 0.1 | M5: 47 | N5: 48 | O5: 43 | P5: 5 | Q5: 8 | R5: 0.055176051 | U5: sample size per cluster | V5: ICC | W5: Marge d'erreur
A6: CM004 | B6: Extrême-Nord | C6: CM004001 | D6: Diamaré | E6: CM004001005 | F6: Maroua 2e | G6: 290.33333 | H6: 0.5 | I6: 0.1 | J6: 0.9 | K6: 0.1 | M6: 61 | N6: 66 | O6: 55 | P6: 11 | Q6: 11 | R6: 0.10688538 | U6: 6 | V6: 0.06 | W6: 0.1
A7: CM004 | B7: Extrême-Nord | C7: CM004001 | D7: Diamaré | E7: CM004001006 | F7: Maroua 3e | G7: 363.5 | H7: 0.5 | I7: 0.1 | J7: 0.9 | K7: 0.1 | M7: 63 | N7: 66 | O7: 57 | P7: 9 | Q7: 11 | R7: 0.13382148
A8: CM004 | B8: Extrême-Nord | C8: CM004001 | D8: Diamaré | E8: CM004001007 | F8: Meri | G8: 0 | H8: 0.5 | I8: 0.1 | J8: 0.9 | K8: 0.1 | M8: 0 | N8: 0 | O8: 0 | P8: 0 | Q8: 0 | R8: #DIV/0!
A9: CM004 | B9: Extrême-Nord | C9: CM004001 | D9: Diamaré | E9: CM004001008 | F9: Ndoukoula | G9: 0 | H9: 0.5 | I9: 0.1 | J9: 0.9 | K9: 0.1 | M9: 0 | N9: 0 | O9: 0 | P9: 0 | Q9: 0 | R9: #DIV/0!
A10: CM004 | B10: Extrême-Nord | C10: CM004001 | D10: Diamaré | E10: CM004001009 | F10: Pette | G10: 453 | H10: 0.5 | I10: 0.1 | J10: 0.9 | K10: 0.1 | M10: 65 | N10: 66 | O10: 59 | P10: 7 | Q10: 11 | R10: 0.16677065
A11: CM004 | B11: Extrême-Nord | C11: CM004002 | D11: Logone-et-Chari | E11: CM004002001 | F11: Blangoua | G11: 5682.6667 | H11: 0.5 | I11: 0.1 | J11: 0.9 | K11: 0.1 | M11: 74 | N11: 78 | O11: 67 | P11: 11 | Q11: 13 | R11: 1.7702024
A12: CM004 | B12: Extrême-Nord | C12: CM004002 | D12: Logone-et-Chari | E12: CM004002002 | F12: Darak | G12: 529.83333 | H12: 0.5 | I12: 0.1 | J12: 0.9 | K12: 0.1 | M12: 66 | N12: 66 | O12: 60 | P12: 6 | Q12: 11 | R12: 0.19505662
A13: CM004 | B13: Extrême-Nord | C13: CM004002 | D13: Logone-et-Chari | E13: CM004002003 | F13: Fotokol | G13: 2438.8333 | H13: 0.5 | I13: 0.1 | J13: 0.9 | K13: 0.1 | M13: 73 | N13: 78 | O13: 66 | P13: 12 | Q13: 13 | R13: 0.7597188
A14: CM004 | B14: Extrême-Nord | C14: CM004002 | D14: Logone-et-Chari | E14: CM004002004 | F14: Goulfey | G14: 1094.6667 | H14: 0.5 | I14: 0.1 | J14: 0.9 | K14: 0.1 | M14: 71 | N14: 72 | O14: 64 | P14: 8 | Q14: 12 | R14: 0.36941519
A15: CM004 | B15: Extrême-Nord | C15: CM004002 | D15: Logone-et-Chari | E15: CM004002005 | F15: Hile-Alifa | G15: 6420.1667 | H15: 0.5 | I15: 0.1 | J15: 0.9 | K15: 0.1 | M15: 74 | N15: 78 | O15: 67 | P15: 11 | Q15: 13 | R15: 1.9999404
A16: CM004 | B16: Extrême-Nord | C16: CM004002 | D16: Logone-et-Chari | E16: CM004002006 | F16: Kousseri | G16: 885.83333 | H16: 0.5 | I16: 0.1 | J16: 0.9 | K16: 0.1 | M16: 70 | N16: 72 | O16: 63 | P16: 9 | Q16: 12 | R16: 0.29894058
A17: CM004 | B17: Extrême-Nord | C17: CM004002 | D17: Logone-et-Chari | E17: CM004002007 | F17: Logone-Birni | G17: 1955 | H17: 0.5 | I17: 0.1 | J17: 0.9 | K17: 0.1 | M17: 72 | N17: 72 | O17: 65 | P17: 7 | Q17: 12 | R17: 0.65975033
A18: CM004 | B18: Extrême-Nord | C18: CM004002 | D18: Logone-et-Chari | E18: CM004002008 | F18: Makary | G18: 10014.333 | H18: 0.5 | I18: 0.1 | J18: 0.9 | K18: 0.1 | M18: 74 | N18: 78 | O18: 67 | P18: 11 | Q18: 13 | R18: 3.119556
A19: CM004 | B19: Extrême-Nord | C19: CM004002 | D19: Logone-et-Chari | E19: CM004002009 | F19: Waza | G19: 1256.5 | H19: 0.5 | I19: 0.1 | J19: 0.9 | K19: 0.1 | M19: 71 | N19: 72 | O19: 64 | P19: 8 | Q19: 12 | R19: 0.42402879
A20: CM004 | B20: Extrême-Nord | C20: CM004002 | D20: Logone-et-Chari | E20: CM004002010 | F20: Zina | G20: 0 | H20: 0.5 | I20: 0.1 | J20: 0.9 | K20: 0.1 | M20: 0 | N20: 0 | O20: 0 | P20: 0 | Q20: 0 | R20: #DIV/0!
A21: CM004 | B21: Extrême-Nord | C21: CM004003 | D21: Mayo-Danay | E21: CM004003001 | F21: Datcheka | G21: 0 | H21: 0.5 | I21: 0.1 | J21: 0.9 | K21: 0.1 | M21: 0 | N21: 0 | O21: 0 | P21: 0 | Q21: 0 | R21: #DIV/0!
A22: CM004 | B22: Extrême-Nord | C22: CM004003 | D22: Mayo-Danay | E22: CM004003002 | F22: Gobo | G22: 331.5 | H22: 0.5 | I22: 0.1 | J22: 0.9 | K22: 0.1 | M22: 62 | N22: 66 | O22: 56 | P22: 10 | Q22: 11 | R22: 0.12204077
A23: CM004 | B23: Extrême-Nord | C23: CM004003 | D23: Mayo-Danay | E23: CM004003003 | F23: Guere | G23: 0 | H23: 0.5 | I23: 0.1 | J23: 0.9 | K23: 0.1 | M23: 0 | N23: 0 | O23: 0 | P23: 0 | Q23: 0 | R23: #DIV/0!
A24: CM004 | B24: Extrême-Nord | C24: CM004003 | D24: Mayo-Danay | E24: CM004003004 | F24: Kai-Kai | G24: 2346.1667 | H24: 0.5 | I24: 0.1 | J24: 0.9 | K24: 0.1 | M24: 73 | N24: 78 | O24: 66 | P24: 12 | Q24: 13 | R24: 0.73085229
A25: CM004 | B25: Extrême-Nord | C25: CM004003 | D25: Mayo-Danay | E25: CM004003005 | F25: Kalfou | G25: 0 | H25: 0.5 | I25: 0.1 | J25: 0.9 | K25: 0.1 | M25: 0 | N25: 0 | O25: 0 | P25: 0 | Q25: 0 | R25: #DIV/0!
A26: CM004 | B26: Extrême-Nord | C26: CM004003 | D26: Mayo-Danay | E26: CM004003006 | F26: Kar-Hay | G26: 0 | H26: 0.5 | I26: 0.1 | J26: 0.9 | K26: 0.1 | M26: 0 | N26: 0 | O26: 0 | P26: 0 | Q26: 0 | R26: #DIV/0!
A27: CM004 | B27: Extrême-Nord | C27: CM004003 | D27: Mayo-Danay | E27: CM004003007 | F27: Maga | G27: 1001.1667 | H27: 0.5 | I27: 0.1 | J27: 0.9 | K27: 0.1 | M27: 70 | N27: 72 | O27: 63 | P27: 9 | Q27: 12 | R27: 0.33786191
A28: CM004 | B28: Extrême-Nord | C28: CM004003 | D28: Mayo-Danay | E28: CM004003008 | F28: Tchatibali | G28: 0 | H28: 0.5 | I28: 0.1 | J28: 0.9 | K28: 0.1 | M28: 0 | N28: 0 | O28: 0 | P28: 0 | Q28: 0 | R28: #DIV/0!
A29: CM004 | B29: Extrême-Nord | C29: CM004003 | D29: Mayo-Danay | E29: CM004003009 | F29: Vele | G29: 490.5 | H29: 0.5 | I29: 0.1 | J29: 0.9 | K29: 0.1 | M29: 66 | N29: 66 | O29: 60 | P29: 6 | Q29: 11 | R29: 0.18057617
A30: CM004 | B30: Extrême-Nord | C30: CM004003 | D30: Mayo-Danay | E30: CM004003010 | F30: Wina | G30: 0 | H30: 0.5 | I30: 0.1 | J30: 0.9 | K30: 0.1 | M30: 0 | N30: 0 | O30: 0 | P30: 0 | Q30: 0 | R30: #DIV/0!
A31: CM004 | B31: Extrême-Nord | C31: CM004003 | D31: Mayo-Danay | E31: CM004003011 | F31: Yagoua | G31: 182.33333 | H31: 0.5 | I31: 0.1 | J31: 0.9 | K31: 0.1 | M31: 55 | N31: 60 | O31: 50 | P31: 10 | Q31: 10 | R31: 0.073838042
A32: CM004 | B32: Extrême-Nord | C32: CM004004 | D32: Mayo-Kani | E32: CM004004001 | F32: Guidiguis | G32: 0 | H32: 0.5 | I32: 0.1 | J32: 0.9 | K32: 0.1 | M32: 0 | N32: 0 | O32: 0 | P32: 0 | Q32: 0 | R32: #DIV/0!
A33: CM004 | B33: Extrême-Nord | C33: CM004004 | D33: Mayo-Kani | E33: CM004004002 | F33: Kaele | G33: 191.66667 | H33: 0.5 | I33: 0.1 | J33: 0.9 | K33: 0.1 | M33: 55 | N33: 60 | O33: 50 | P33: 10 | Q33: 10 | R33: 0.077617686
A34: CM004 | B34: Extrême-Nord | C34: CM004004 | D34: Mayo-Kani | E34: CM004004003 | F34: Mindif | G34: 0 | H34: 0.5 | I34: 0.1 | J34: 0.9 | K34: 0.1 | M34: 0 | N34: 0 | O34: 0 | P34: 0 | Q34: 0 | R34: #DIV/0!
A35: CM004 | B35: Extrême-Nord | C35: CM004004 | D35: Mayo-Kani | E35: CM004004004 | F35: Moulvoudaye | G35: 577.33333 | H35: 0.5 | I35: 0.1 | J35: 0.9 | K35: 0.1 | M35: 68 | N35: 72 | O35: 62 | P35: 10 | Q35: 12 | R35: 0.19483164
A36: CM004 | B36: Extrême-Nord | C36: CM004004 | D36: Mayo-Kani | E36: CM004004005 | F36: Moutourwa | G36: 0 | H36: 0.5 | I36: 0.1 | J36: 0.9 | K36: 0.1 | M36: 0 | N36: 0 | O36: 0 | P36: 0 | Q36: 0 | R36: #DIV/0!
A37: CM004 | B37: Extrême-Nord | C37: CM004004 | D37: Mayo-Kani | E37: CM004004006 | F37: Porhi | G37: 0 | H37: 0.5 | I37: 0.1 | J37: 0.9 | K37: 0.1 | M37: 0 | N37: 0 | O37: 0 | P37: 0 | Q37: 0 | R37: #DIV/0!
A38: CM004 | B38: Extrême-Nord | C38: CM004004 | D38: Mayo-Kani | E38: CM004004007 | F38: Taibong | G38: 0 | H38: 0.5 | I38: 0.1 | J38: 0.9 | K38: 0.1 | M38: 0 | N38: 0 | O38: 0 | P38: 0 | Q38: 0 | R38: #DIV/0!
A39: CM004 | B39: Extrême-Nord | C39: CM004005 | D39: Mayo-Sava | E39: CM004005001 | F39: Kolofata | G39: 10548.167 | H39: 0.5 | I39: 0.1 | J39: 0.9 | K39: 0.1 | M39: 74 | N39: 78 | O39: 67 | P39: 11 | Q39: 13 | R39: 3.28585
A40: CM004 | B40: Extrême-Nord | C40: CM004005 | D40: Mayo-Sava | E40: CM004005002 | F40: Mora | G40: 12208.5 | H40: 0.5 | I40: 0.1 | J40: 0.9 | K40: 0.1 | M40: 74 | N40: 78 | O40: 67 | P40: 11 | Q40: 13 | R40: 3.8030589
...

Sheet ret
A1: PCODE | B1: Admin1 | C1: PCODE | D1: Admin2 | E1: PCODE | F1: Admin3 | G1: Pop admin3 | H1: p | I1: buffer | J1: ci (AE8) | K1: marge d'erreur | M1: sample admin2 | N1: final adjusted up to multiple of 6 | O1: enquete a faire sans buffer | P1: enquetes de buffer | Q1: nombre de clusters à tirer | R1: weights adjusted
A2: CM004 | B2: Extrême-Nord | C2: CM004001 | D2: Diamaré | E2: CM004001001 | F2: Bogo | G2: 0 | H2: 0.5 | I2: 0.1 | J2: 0.9 | K2: 0.1 | M2: 0 | N2: 0 | O2: 0 | P2: 0 | Q2: 0 | R2: #DIV/0!
A3: CM004 | B3: Extrême-Nord | C3: CM004001 | D3: Diamaré | E3: CM004001002 | F3: Dargala | G3: 0 | H3: 0.5 | I3: 0.1 | J3: 0.9 | K3: 0.1 | M3: 0 | N3: 0 | O3: 0 | P3: 0 | Q3: 0 | R3: #DIV/0!
A4: CM004 | B4: Extrême-Nord | C4: CM004001 | D4: Diamaré | E4: CM004001003 | F4: Gazawa | G4: 0 | H4: 0.5 | I4: 0.1 | J4: 0.9 | K4: 0.1 | M4: 0 | N4: 0 | O4: 0 | P4: 0 | Q4: 0 | R4: #DIV/0!
A5: CM004 | B5: Extrême-Nord | C5: CM004001 | D5: Diamaré | E5: CM004001004 | F5: Maroua 1er | G5: 0 | H5: 0.5 | I5: 0.1 | J5: 0.9 | K5: 0.1 | M5: 0 | N5: 0 | O5: 0 | P5: 0 | Q5: 0 | R5: #DIV/0! | U5: sample size per cluster | V5: ICC | W5: Marge d'erreur
A6: CM004 | B6: Extrême-Nord | C6: CM004001 | D6: Diamaré | E6: CM004001005 | F6: Maroua 2e | G6: 0 | H6: 0.5 | I6: 0.1 | J6: 0.9 | K6: 0.1 | M6: 0 | N6: 0 | O6: 0 | P6: 0 | Q6: 0 | R6: #DIV/0! | U6: 6 | V6: 0.06 | W6: 0.1
A7: CM004 | B7: Extrême-Nord | C7: CM004001 | D7: Diamaré | E7: CM004001006 | F7: Maroua 3e | G7: 0 | H7: 0.5 | I7: 0.1 | J7: 0.9 | K7: 0.1 | M7: 0 | N7: 0 | O7: 0 | P7: 0 | Q7: 0 | R7: #DIV/0!
A8: CM004 | B8: Extrême-Nord | C8: CM004001 | D8: Diamaré | E8: CM004001007 | F8: Meri | G8: 0 | H8: 0.5 | I8: 0.1 | J8: 0.9 | K8: 0.1 | M8: 0 | N8: 0 | O8: 0 | P8: 0 | Q8: 0 | R8: #DIV/0!
A9: CM004 | B9: Extrême-Nord | C9: CM004001 | D9: Diamaré | E9: CM004001008 | F9: Ndoukoula | G9: 0 | H9: 0.5 | I9: 0.1 | J9: 0.9 | K9: 0.1 | M9: 0 | N9: 0 | O9: 0 | P9: 0 | Q9: 0 | R9: #DIV/0!
A10: CM004 | B10: Extrême-Nord | C10: CM004001 | D10: Diamaré | E10: CM004001009 | F10: Pette | G10: 0 | H10: 0.5 | I10: 0.1 | J10: 0.9 | K10: 0.1 | M10: 0 | N10: 0 | O10: 0 | P10: 0 | Q10: 0 | R10: #DIV/0!
A11: CM004 | B11: Extrême-Nord | C11: CM004002 | D11: Logone-et-Chari | E11: CM004002001 | F11: Blangoua | G11: 281.33333 | H11: 0.5 | I11: 0.1 | J11: 0.9 | K11: 0.1 | M11: 61 | N11: 66 | O11: 55 | P11: 11 | Q11: 11 | R11: 0.14326363
A12: CM004 | B12: Extrême-Nord | C12: CM004002 | D12: Logone-et-Chari | E12: CM004002002 | F12: Darak | G12: 0 | H12: 0.5 | I12: 0.1 | J12: 0.9 | K12: 0.1 | M12: 0 | N12: 0 | O12: 0 | P12: 0 | Q12: 0 | R12: #DIV/0!
A13: CM004 | B13: Extrême-Nord | C13: CM004002 | D13: Logone-et-Chari | E13: CM004002003 | F13: Fotokol | G13: 2221.3333 | H13: 0.5 | I13: 0.1 | J13: 0.9 | K13: 0.1 | M13: 73 | N13: 78 | O13: 66 | P13: 12 | Q13: 13 | R13: 0.95714518
A14: CM004 | B14: Extrême-Nord | C14: CM004002 | D14: Logone-et-Chari | E14: CM004002004 | F14: Goulfey | G14: 111.5 | H14: 0.5 | I14: 0.1 | J14: 0.9 | K14: 0.1 | M14: 47 | N14: 48 | O14: 43 | P14: 5 | Q14: 8 | R14: 0.078071463
A15: CM004 | B15: Extrême-Nord | C15: CM004002 | D15: Logone-et-Chari | E15: CM004002005 | F15: Hile-Alifa | G15: 0 | H15: 0.5 | I15: 0.1 | J15: 0.9 | K15: 0.1 | M15: 0 | N15: 0 | O15: 0 | P15: 0 | Q15: 0 | R15: #DIV/0!
A16: CM004 | B16: Extrême-Nord | C16: CM004002 | D16: Logone-et-Chari | E16: CM004002006 | F16: Kousseri | G16: 3998.3333 | H16: 0.5 | I16: 0.1 | J16: 0.9 | K16: 0.1 | M16: 74 | N16: 78 | O16: 67 | P16: 11 | Q16: 13 | R16: 1.7228326
A17: CM004 | B17: Extrême-Nord | C17: CM004002 | D17: Logone-et-Chari | E17: CM004002007 | F17: Logone-Birni | G17: 3782.5 | H17: 0.5 | I17: 0.1 | J17: 0.9 | K17: 0.1 | M17: 73 | N17: 78 | O17: 66 | P17: 12 | Q17: 13 | R17: 1.6298327
A18: CM004 | B18: Extrême-Nord | C18: CM004002 | D18: Logone-et-Chari | E18: CM004002008 | F18: Makary | G18: 432.66667 | H18: 0.5 | I18: 0.1 | J18: 0.9 | K18: 0.1 | M18: 65 | N18: 66 | O18: 59 | P18: 7 | Q18: 11 | R18: 0.22032724
A19: CM004 | B19: Extrême-Nord | C19: CM004002 | D19: Logone-et-Chari | E19: CM004002009 | F19: Waza | G19: 407.33333 | H19: 0.5 | I19: 0.1 | J19: 0.9 | K19: 0.1 | M19: 64 | N19: 66 | O19: 58 | P19: 8 | Q19: 11 | R19: 0.20742672
A20: CM004 | B20: Extrême-Nord | C20: CM004002 | D20: Logone-et-Chari | E20: CM004002010 | F20: Zina | G20: 0 | H20: 0.5 | I20: 0.1 | J20: 0.9 | K20: 0.1 | M20: 0 | N20: 0 | O20: 0 | P20: 0 | Q20: 0 | R20: #DIV/0!
A21: CM004 | B21: Extrême-Nord | C21: CM004003 | D21: Mayo-Danay | E21: CM004003001 | F21: Datcheka | G21: 2436.5 | H21: 0.5 | I21: 0.1 | J21: 0.9 | K21: 0.1 | M21: 73 | N21: 78 | O21: 66 | P21: 12 | Q21: 13 | R21: 1.0498579
A22: CM004 | B22: Extrême-Nord | C22: CM004003 | D22: Mayo-Danay | E22: CM004003002 | F22: Gobo | G22: 1820.3333 | H22: 0.5 | I22: 0.1 | J22: 0.9 | K22: 0.1 | M22: 72 | N22: 72 | O22: 65 | P22: 7 | Q22: 12 | R22: 0.84972249
A23: CM004 | B23: Extrême-Nord | C23: CM004003 | D23: Mayo-Danay | E23: CM004003003 | F23: Guere | G23: 399 | H23: 0.5 | I23: 0.1 | J23: 0.9 | K23: 0.1 | M23: 64 | N23: 66 | O23: 58 | P23: 8 | Q23: 11 | R23: 0.20318313
A24: CM004 | B24: Extrême-Nord | C24: CM004003 | D24: Mayo-Danay | E24: CM004003004 | F24: Kai-Kai | G24: 2594.1667 | H24: 0.5 | I24: 0.1 | J24: 0.9 | K24: 0.1 | M24: 73 | N24: 78 | O24: 66 | P24: 12 | Q24: 13 | R24: 1.1177945
A25: CM004 | B25: Extrême-Nord | C25: CM004003 | D25: Mayo-Danay | E25: CM004003005 | F25: Kalfou | G25: 0 | H25: 0.5 | I25: 0.1 | J25: 0.9 | K25: 0.1 | M25: 0 | N25: 0 | O25: 0 | P25: 0 | Q25: 0 | R25: #DIV/0!
A26: CM004 | B26: Extrême-Nord | C26: CM004003 | D26: Mayo-Danay | E26: CM004003006 | F26: Kar-Hay | G26: 2839.6667 | H26: 0.5 | I26: 0.1 | J26: 0.9 | K26: 0.1 | M26: 73 | N26: 78 | O26: 66 | P26: 12 | Q26: 13 | R26: 1.2235774
A27: CM004 | B27: Extrême-Nord | C27: CM004003 | D27: Mayo-Danay | E27: CM004003007 | F27: Maga | G27: 3698.1667 | H27: 0.5 | I27: 0.1 | J27: 0.9 | K27: 0.1 | M27: 73 | N27: 78 | O27: 66 | P27: 12 | Q27: 13 | R27: 1.5934945
A28: CM004 | B28: Extrême-Nord | C28: CM004003 | D28: Mayo-Danay | E28: CM004003008 | F28: Tchatibali | G28: 2760.5 | H28: 0.5 | I28: 0.1 | J28: 0.9 | K28: 0.1 | M28: 73 | N28: 78 | O28: 66 | P28: 12 | Q28: 13 | R28: 1.1894655
A29: CM004 | B29: Extrême-Nord | C29: CM004003 | D29: Mayo-Danay | E29: CM004003009 | F29: Vele | G29: 4101.1667 | H29: 0.5 | I29: 0.1 | J29: 0.9 | K29: 0.1 | M29: 74 | N29: 78 | O29: 67 | P29: 11 | Q29: 13 | R29: 1.7671422
A30: CM004 | B30: Extrême-Nord | C30: CM004003 | D30: Mayo-Danay | E30: CM004003010 | F30: Wina | G30: 6069.6667 | H30: 0.5 | I30: 0.1 | J30: 0.9 | K30: 0.1 | M30: 74 | N30: 78 | O30: 67 | P30: 11 | Q30: 13 | R30: 2.6153446
A31: CM004 | B31: Extrême-Nord | C31: CM004003 | D31: Mayo-Danay | E31: CM004003011 | F31: Yagoua | G31: 1310.3333 | H31: 0.5 | I31: 0.1 | J31: 0.9 | K31: 0.1 | M31: 71 | N31: 72 | O31: 64 | P31: 8 | Q31: 12 | R31: 0.61165704
A32: CM004 | B32: Extrême-Nord | C32: CM004004 | D32: Mayo-Kani | E32: CM004004001 | F32: Guidiguis | G32: 0 | H32: 0.5 | I32: 0.1 | J32: 0.9 | K32: 0.1 | M32: 0 | N32: 0 | O32: 0 | P32: 0 | Q32: 0 | R32: #DIV/0!
A33: CM004 | B33: Extrême-Nord | C33: CM004004 | D33: Mayo-Kani | E33: CM004004002 | F33: Kaele | G33: 0 | H33: 0.5 | I33: 0.1 | J33: 0.9 | K33: 0.1 | M33: 0 | N33: 0 | O33: 0 | P33: 0 | Q33: 0 | R33: #DIV/0!
A34: CM004 | B34: Extrême-Nord | C34: CM004004 | D34: Mayo-Kani | E34: CM004004003 | F34: Mindif | G34: 0 | H34: 0.5 | I34: 0.1 | J34: 0.9 | K34: 0.1 | M34: 0 | N34: 0 | O34: 0 | P34: 0 | Q34: 0 | R34: #DIV/0!
A35: CM004 | B35: Extrême-Nord | C35: CM004004 | D35: Mayo-Kani | E35: CM004004004 | F35: Moulvoudaye | G35: 0 | H35: 0.5 | I35: 0.1 | J35: 0.9 | K35: 0.1 | M35: 0 | N35: 0 | O35: 0 | P35: 0 | Q35: 0 | R35: #DIV/0!
A36: CM004 | B36: Extrême-Nord | C36: CM004004 | D36: Mayo-Kani | E36: CM004004005 | F36: Moutourwa | G36: 0 | H36: 0.5 | I36: 0.1 | J36: 0.9 | K36: 0.1 | M36: 0 | N36: 0 | O36: 0 | P36: 0 | Q36: 0 | R36: #DIV/0!
A37: CM004 | B37: Extrême-Nord | C37: CM004004 | D37: Mayo-Kani | E37: CM004004006 | F37: Porhi | G37: 0 | H37: 0.5 | I37: 0.1 | J37: 0.9 | K37: 0.1 | M37: 0 | N37: 0 | O37: 0 | P37: 0 | Q37: 0 | R37: #DIV/0!
A38: CM004 | B38: Extrême-Nord | C38: CM004004 | D38: Mayo-Kani | E38: CM004004007 | F38: Taibong | G38: 0 | H38: 0.5 | I38: 0.1 | J38: 0.9 | K38: 0.1 | M38: 0 | N38: 0 | O38: 0 | P38: 0 | Q38: 0 | R38: #DIV/0!
A39: CM004 | B39: Extrême-Nord | C39: CM004005 | D39: Mayo-Sava | E39: CM004005001 | F39: Kolofata | G39: 3237 | H39: 0.5 | I39: 0.1 | J39: 0.9 | K39: 0.1 | M39: 73 | N39: 78 | O39: 66 | P39: 12 | Q39: 13 | R39: 1.3947834
A40: CM004 | B40: Extrême-Nord | C40: CM004005 | D40: Mayo-Sava | E40: CM004005002 | F40: Mora | G40: 3203 | H40: 0.5 | I40: 0.1 | J40: 0.9 | K40: 0.1 | M40: 73 | N40: 78 | O40: 66 | P40: 12 | Q40: 13 | R40: 1.3801333
...

Sheet ref
A1: PCODE | B1: Admin1 | C1: PCODE | D1: Admin2 | E1: PCODE | F1: Admin3 | G1: Pop admin3 | H1: p | I1: buffer | J1: ci (AE8) | K1: marge d'erreur | M1: sample admin2 | N1: final adjusted up to multiple of 6 | O1: enquete a faire sans buffer | P1: enquetes de buffer | Q1: nombre de clusters à tirer | R1: weights adjusted
A2: CM004 | B2: Extrême-Nord | C2: CM004001 | D2: Diamaré | E2: CM004001001 | F2: Bogo | G2: 0 | H2: 0.5 | I2: 0.1 | J2: 0.9 | K2: 0.1 | M2: 0 | N2: 0 | O2: 0 | P2: 0 | Q2: 0 | R2: #DIV/0!
A3: CM004 | B3: Extrême-Nord | C3: CM004001 | D3: Diamaré | E3: CM004001002 | F3: Dargala | G3: 0 | H3: 0.5 | I3: 0.1 | J3: 0.9 | K3: 0.1 | M3: 0 | N3: 0 | O3: 0 | P3: 0 | Q3: 0 | R3: #DIV/0!
A4: CM004 | B4: Extrême-Nord | C4: CM004001 | D4: Diamaré | E4: CM004001003 | F4: Gazawa | G4: 0 | H4: 0.5 | I4: 0.1 | J4: 0.9 | K4: 0.1 | M4: 0 | N4: 0 | O4: 0 | P4: 0 | Q4: 0 | R4: #DIV/0!
A5: CM004 | B5: Extrême-Nord | C5: CM004001 | D5: Diamaré | E5: CM004001004 | F5: Maroua 1er | G5: 0 | H5: 0.5 | I5: 0.1 | J5: 0.9 | K5: 0.1 | M5: 0 | N5: 0 | O5: 0 | P5: 0 | Q5: 0 | R5: #DIV/0! | U5: sample size per cluster | V5: ICC | W5: Marge d'erreur
A6: CM004 | B6: Extrême-Nord | C6: CM004001 | D6: Diamaré | E6: CM004001005 | F6: Maroua 2e | G6: 0 | H6: 0.5 | I6: 0.1 | J6: 0.9 | K6: 0.1 | M6: 0 | N6: 0 | O6: 0 | P6: 0 | Q6: 0 | R6: #DIV/0! | U6: 6 | V6: 0.06 | W6: 0.1
A7: CM004 | B7: Extrême-Nord | C7: CM004001 | D7: Diamaré | E7: CM004001006 | F7: Maroua 3e | G7: 0 | H7: 0.5 | I7: 0.1 | J7: 0.9 | K7: 0.1 | M7: 0 | N7: 0 | O7: 0 | P7: 0 | Q7: 0 | R7: #DIV/0!
A8: CM004 | B8: Extrême-Nord | C8: CM004001 | D8: Diamaré | E8: CM004001007 | F8: Meri | G8: 0 | H8: 0.5 | I8: 0.1 | J8: 0.9 | K8: 0.1 | M8: 0 | N8: 0 | O8: 0 | P8: 0 | Q8: 0 | R8: #DIV/0!
A9: CM004 | B9: Extrême-Nord | C9: CM004001 | D9: Diamaré | E9: CM004001008 | F9: Ndoukoula | G9: 0 | H9: 0.5 | I9: 0.1 | J9: 0.9 | K9: 0.1 | M9: 0 | N9: 0 | O9: 0 | P9: 0 | Q9: 0 | R9: #DIV/0!
A10: CM004 | B10: Extrême-Nord | C10: CM004001 | D10: Diamaré | E10: CM004001009 | F10: Pette | G10: 0 | H10: 0.5 | I10: 0.1 | J10: 0.9 | K10: 0.1 | M10: 0 | N10: 0 | O10: 0 | P10: 0 | Q10: 0 | R10: #DIV/0!
A11: CM004 | B11: Extrême-Nord | C11: CM004002 | D11: Logone-et-Chari | E11: CM004002001 | F11: Blangoua | G11: 0 | H11: 0.5 | I11: 0.1 | J11: 0.9 | K11: 0.1 | M11: 0 | N11: 0 | O11: 0 | P11: 0 | Q11: 0 | R11: #DIV/0!
A12: CM004 | B12: Extrême-Nord | C12: CM004002 | D12: Logone-et-Chari | E12: CM004002002 | F12: Darak | G12: 0 | H12: 0.5 | I12: 0.1 | J12: 0.9 | K12: 0.1 | M12: 0 | N12: 0 | O12: 0 | P12: 0 | Q12: 0 | R12: #DIV/0!
A13: CM004 | B13: Extrême-Nord | C13: CM004002 | D13: Logone-et-Chari | E13: CM004002003 | F13: Fotokol | G13: 598 | H13: 0.5 | I13: 0.1 | J13: 0.9 | K13: 0.1 | M13: 68 | N13: 72 | O13: 62 | P13: 10 | Q13: 12 | R13: 0.2110777
A14: CM004 | B14: Extrême-Nord | C14: CM004002 | D14: Logone-et-Chari | E14: CM004002004 | F14: Goulfey | G14: 0 | H14: 0.5 | I14: 0.1 | J14: 0.9 | K14: 0.1 | M14: 0 | N14: 0 | O14: 0 | P14: 0 | Q14: 0 | R14: #DIV/0!
A15: CM004 | B15: Extrême-Nord | C15: CM004002 | D15: Logone-et-Chari | E15: CM004002005 | F15: Hile-Alifa | G15: 0 | H15: 0.5 | I15: 0.1 | J15: 0.9 | K15: 0.1 | M15: 0 | N15: 0 | O15: 0 | P15: 0 | Q15: 0 | R15: #DIV/0!
A16: CM004 | B16: Extrême-Nord | C16: CM004002 | D16: Logone-et-Chari | E16: CM004002006 | F16: Kousseri | G16: 589 | H16: 0.5 | I16: 0.1 | J16: 0.9 | K16: 0.1 | M16: 68 | N16: 72 | O16: 62 | P16: 10 | Q16: 12 | R16: 0.20790094
A17: CM004 | B17: Extrême-Nord | C17: CM004002 | D17: Logone-et-Chari | E17: CM004002007 | F17: Logone-Birni | G17: 116 | H17: 0.5 | I17: 0.1 | J17: 0.9 | K17: 0.1 | M17: 48 | N17: 48 | O17: 44 | P17: 4 | Q17: 8 | R17: 0.061417256
A18: CM004 | B18: Extrême-Nord | C18: CM004002 | D18: Logone-et-Chari | E18: CM004002008 | F18: Makary | G18: 2686 | H18: 0.5 | I18: 0.1 | J18: 0.9 | K18: 0.1 | M18: 73 | N18: 78 | O18: 66 | P18: 12 | Q18: 13 | R18: 0.87515517
A19: CM004 | B19: Extrême-Nord | C19: CM004002 | D19: Logone-et-Chari | E19: CM004002009 | F19: Waza | G19: 1338 | H19: 0.5 | I19: 0.1 | J19: 0.9 | K19: 0.1 | M19: 71 | N19: 72 | O19: 64 | P19: 8 | Q19: 12 | R19: 0.47227752
A20: CM004 | B20: Extrême-Nord | C20: CM004002 | D20: Logone-et-Chari | E20: CM004002010 | F20: Zina | G20: 0 | H20: 0.5 | I20: 0.1 | J20: 0.9 | K20: 0.1 | M20: 0 | N20: 0 | O20: 0 | P20: 0 | Q20: 0 | R20: #DIV/0!
A21: CM004 | B21: Extrême-Nord | C21: CM004003 | D21: Mayo-Danay | E21: CM004003001 | F21: Datcheka | G21: 0 | H21: 0.5 | I21: 0.1 | J21: 0.9 | K21: 0.1 | M21: 0 | N21: 0 | O21: 0 | P21: 0 | Q21: 0 | R21: #DIV/0!
A22: CM004 | B22: Extrême-Nord | C22: CM004003 | D22: Mayo-Danay | E22: CM004003002 | F22: Gobo | G22: 0 | H22: 0.5 | I22: 0.1 | J22: 0.9 | K22: 0.1 | M22: 0 | N22: 0 | O22: 0 | P22: 0 | Q22: 0 | R22: #DIV/0!
A23: CM004 | B23: Extrême-Nord | C23: CM004003 | D23: Mayo-Danay | E23: CM004003003 | F23: Guere | G23: 0 | H23: 0.5 | I23: 0.1 | J23: 0.9 | K23: 0.1 | M23: 0 | N23: 0 | O23: 0 | P23: 0 | Q23: 0 | R23: #DIV/0!
A24: CM004 | B24: Extrême-Nord | C24: CM004003 | D24: Mayo-Danay | E24: CM004003004 | F24: Kai-Kai | G24: 0 | H24: 0.5 | I24: 0.1 | J24: 0.9 | K24: 0.1 | M24: 0 | N24: 0 | O24: 0 | P24: 0 | Q24: 0 | R24: #DIV/0!
A25: CM004 | B25: Extrême-Nord | C25: CM004003 | D25: Mayo-Danay | E25: CM004003005 | F25: Kalfou | G25: 0 | H25: 0.5 | I25: 0.1 | J25: 0.9 | K25: 0.1 | M25: 0 | N25: 0 | O25: 0 | P25: 0 | Q25: 0 | R25: #DIV/0!
A26: CM004 | B26: Extrême-Nord | C26: CM004003 | D26: Mayo-Danay | E26: CM004003006 | F26: Kar-Hay | G26: 0 | H26: 0.5 | I26: 0.1 | J26: 0.9 | K26: 0.1 | M26: 0 | N26: 0 | O26: 0 | P26: 0 | Q26: 0 | R26: #DIV/0!
A27: CM004 | B27: Extrême-Nord | C27: CM004003 | D27: Mayo-Danay | E27: CM004003007 | F27: Maga | G27: 0 | H27: 0.5 | I27: 0.1 | J27: 0.9 | K27: 0.1 | M27: 0 | N27: 0 | O27: 0 | P27: 0 | Q27: 0 | R27: #DIV/0!
A28: CM004 | B28: Extrême-Nord | C28: CM004003 | D28: Mayo-Danay | E28: CM004003008 | F28: Tchatibali | G28: 0 | H28: 0.5 | I28: 0.1 | J28: 0.9 | K28: 0.1 | M28: 0 | N28: 0 | O28: 0 | P28: 0 | Q28: 0 | R28: #DIV/0!
A29: CM004 | B29: Extrême-Nord | C29: CM004003 | D29: Mayo-Danay | E29: CM004003009 | F29: Vele | G29: 0 | H29: 0.5 | I29: 0.1 | J29: 0.9 | K29: 0.1 | M29: 0 | N29: 0 | O29: 0 | P29: 0 | Q29: 0 | R29: #DIV/0!
A30: CM004 | B30: Extrême-Nord | C30: CM004003 | D30: Mayo-Danay | E30: CM004003010 | F30: Wina | G30: 0 | H30: 0.5 | I30: 0.1 | J30: 0.9 | K30: 0.1 | M30: 0 | N30: 0 | O30: 0 | P30: 0 | Q30: 0 | R30: #DIV/0!
A31: CM004 | B31: Extrême-Nord | C31: CM004003 | D31: Mayo-Danay | E31: CM004003011 | F31: Yagoua | G31: 0 | H31: 0.5 | I31: 0.1 | J31: 0.9 | K31: 0.1 | M31: 0 | N31: 0 | O31: 0 | P31: 0 | Q31: 0 | R31: #DIV/0!
... A39: CM004 | B39: Extrême-Nord | C39: CM004005 | D39: Mayo-Sava | E39: CM004005001 | F39: Kolofata | G39: 0 | H39: 0.5 | I39: 0.1 | J39: 0.9 | K39: 0.1 | M39: 0 | N39: 0 | O39: 0 | P39: 0 | Q39: 0 | R39: #DIV/0!
A40: CM004 | B40: Extrême-Nord | C40: CM004005 | D40: Mayo-Sava | E40: CM004005002 | F40: Mora | G40: 1499 | H40: 0.5 | I40: 0.1 | J40: 0.9 | K40: 0.1 | M40: 72 | N40: 72 | O40: 65 | P40: 7 | Q40: 12 | R40: 0.52910613
A41: CM004 | B41: Extrême-Nord | C41: CM004005 | D41: Mayo-Sava | E41: CM004005003 | F41: Tokombere | G41: 0 | H41: 0.5 | I41: 0.1 | J41: 0.9 | K41: 0.1 | M41: 0 | N41: 0 | O41: 0 | P41: 0 | Q41: 0 | R41: #DIV/0!
A42: CM004 | B42: Extrême-Nord | C42: CM004006 | D42: Mayo-Tsanaga | E42: CM004006001 | F42: Bourrha | G42: 0 | H42: 0.5 | I42: 0.1 | J42: 0.9 | K42: 0.1 | M42: 0 | N42: 0 | O42: 0 | P42: 0 | Q42: 0 | R42: #DIV/0!
A43: CM004 | B43: Extrême-Nord | C43: CM004006 | D43: Mayo-Tsanaga | E43: CM004006002 | F43: Hina | G43: 0 | H43: 0.5 | I43: 0.1 | J43: 0.9 | K43: 0.1 | M43: 0 | N43: 0 | O43: 0 | P43: 0 | Q43: 0 | R43: #DIV/0!
A44: CM004 | B44: Extrême-Nord | C44: CM004006 | D44: Mayo-Tsanaga | E44: CM004006003 | F44: Koza | G44: 0 | H44: 0.5 | I44: 0.1 | J44: 0.9 | K44: 0.1 | M44: 0 | N44: 0 | O44: 0 | P44: 0 | Q44: 0 | R44: #DIV/0!
A45: CM004 | B45: Extrême-Nord | C45: CM004006 | D45: Mayo-Tsanaga | E45: CM004006004 | F45: Mayo-Moskota | G45: 112 | H45: 0.5 | I45: 0.1 | J45: 0.9 | K45: 0.1 | M45: 47 | N45: 48 | O45: 43 | P45: 5 | Q45: 8 | R45: 0.05929942
A46: CM004 | B46: Extrême-Nord | C46: CM004006 | D46: Mayo-Tsanaga | E46: CM004006005 | F46: Mogode | G46: 0 | H46: 0.5 | I46: 0.1 | J46: 0.9 | K46: 0.1 | M46: 0 | N46: 0 | O46: 0 | P46: 0 | Q46: 0 | R46: #DIV/0!
A47: CM004 | B47: Extrême-Nord | C47: CM004006 | D47: Mayo-Tsanaga | E47: CM004006006 | F47: Mokolo | G47: 262 | H47: 0.5 | I47: 0.1 | J47: 0.9 | K47: 0.1 | M47: 60 | N47: 60 | O47: 54 | P47: 6 | Q47: 10 | R47: 0.11097463
...

Sheet sampling ZME
A1: LZNAMEFR | B1: CLASS | C1: survey_ZME

Sheet Sheet1
A1: adm3_name | B1: adm3_pcode | C1: adm2_pcode | D1: population_admin2 | E1: population_admin3 | F1: proportion | I1: enquete | J1: cluster
A2: Mangodara | B2: BF470103 | C2: BF4701 | D2: 624409.14 | E2: 50514.39 | F2: =E2/D2 -> 0.080899504 | G2: =VLOOKUP(C2,host!F:O,9,0) -> #N/A | H2: =+G2*F2 -> #N/A | I2: =ROUND(H2,0) -> #N/A | J2: =ROUND(I2/4,0) -> #N/A
A3: Batie | B3: BF570301 | C3: BF5703 | D3: 16079.324 | E3: 14629.306 | F3: =E3/D3 -> 0.90982095 | G3: =VLOOKUP(C3,host!F:O,9,0) -> #N/A | H3: =+G3*F3 -> #N/A | I3: =ROUND(H3,0) -> #N/A | J3: =ROUND(I3/4,0) -> #N/A
A4: Niangoloko | B4: BF470105 | C4: BF4701 | D4: 624409.14 | E4: 65166.7 | F4: =E4/D4 -> 0.10436538 | G4: =VLOOKUP(C4,host!F:O,9,0) -> #N/A | H4: =+G4*F4 -> #N/A | I4: =ROUND(H4,0) -> #N/A | J4: =ROUND(I4/4,0) -> #N/A
A5: Ouo | B5: BF470106 | C5: BF4701 | D5: 624409.14 | E5: 75279.507 | F5: =E5/D5 -> 0.12056119 | G5: =VLOOKUP(C5,host!F:O,9,0) -> #N/A | H5: =+G5*F5 -> #N/A | I5: =ROUND(H5,0) -> #N/A | J5: =ROUND(I5/4,0) -> #N/A
A6: Djigoue | B6: BF570403 | C6: BF5704 | D6: 198221.46 | E6: 10771.427 | F6: =E6/D6 -> 0.05434037 | G6: =VLOOKUP(C6,host!F:O,9,0) -> #N/A | H6: =+G6*F6 -> #N/A | I6: =ROUND(H6,0) -> #N/A | J6: =ROUND(I6/4,0) -> #N/A
A7: Kampti | B7: BF570406 | C7: BF5704 | D7: 198221.46 | E7: 30653.844 | F7: =E7/D7 -> 0.15464443 | G7: =VLOOKUP(C7,host!F:O,9,0) -> #N/A | H7: =+G7*F7 -> #N/A | I7: =ROUND(H7,0) -> #N/A | J7: =ROUND(I7/4,0) -> #N/A
A8: Midebdo | B8: BF570305 | C8: BF5703 | D8: 16079.324 | E8: 635.72331 | F8: =E8/D8 -> 0.039536694 | G8: =VLOOKUP(C8,host!F:O,9,0) -> #N/A | H8: =+G8*F8 -> #N/A | I8: =ROUND(H8,0) -> #N/A | J8: =ROUND(I8/4,0) -> #N/A
A9: Perigban | B9: BF570410 | C9: BF5704 | D9: 198221.46 | E9: 5022.1926 | F9: =E9/D9 -> 0.025336271 | G9: =VLOOKUP(C9,host!F:O,9,0) -> #N/A | H9: =+G9*F9 -> #N/A | I9: =ROUND(H9,0) -> #N/A | J9: =ROUND(I9/4,0) -> #N/A
A10: Legmoin | B10: BF570304 | C10: BF5703 | D10: 16079.324 | E10: 814.2949 | F10: =E10/D10 -> 0.05064236 | G10: =VLOOKUP(C10,host!F:O,9,0) -> #N/A | H10: =+G10*F10 -> #N/A | I10: =ROUND(H10,0) -> #N/A | J10: =ROUND(I10/4,0) -> #N/A
A11: Sideradougou | B11: BF470107 | C11: BF4701 | D11: 624409.14 | E11: 147859.22 | F11: =E11/D11 -> 0.23679861 | G11: =VLOOKUP(C11,host!F:O,9,0) -> #N/A | H11: =+G11*F11 -> #N/A | I11: =ROUND(H11,0) -> #N/A | J11: =ROUND(I11/4,0) -> #N/A
A12: Gbomblora | B12: BF570405 | C12: BF5704 | D12: 198221.46 | E12: 11419.039 | F12: =E12/D12 -> 0.05760748 | G12: =VLOOKUP(C12,host!F:O,9,0) -> #N/A | H12: =+G12*F12 -> #N/A | I12: =ROUND(H12,0) -> #N/A | J12: =ROUND(I12/4,0) -> #N/A
A13: Gaoua | B13: BF570404 | C13: BF5704 | D13: 198221.46 | E13: 60075.03 | F13: =E13/D13 -> 0.30307026 | G13: =VLOOKUP(C13,host!F:O,9,0) -> #N/A | H13: =+G13*F13 -> #N/A | I13: =ROUND(H13,0) -> #N/A | J13: =ROUND(I13/4,0) -> #N/A
... A300: Thiou | B300: BF540312 | C300: BF5403 | D300: 494996.35 | E300: 28154.822 | F300: =E300/D300 -> 0.056878847 | G300: =VLOOKUP(C300,host!F:O,9,0) -> #N/A | H300: =+G300*F300 -> #N/A | I300: =ROUND(H300,0) -> #N/A | J300: =ROUND(I300/4,0) -> #N/A
